Workbook

Sheet Summary
C1: Improving how we connect: ROM Costing Spreadsheet - Operational Costs | F1: DRAFT
A4: API -> | C4: API Operational Costs - Monthly - Original Supplier Version, with Relative Hosting Cost | G4: API Operational Costs - Monthly - Original Supplier Run/Maintain, but with Bottom-up hosting cost | K4: API Operational Costs - Monthly - All NHSE Staff Version, with Bottom-up hosting cost | O4: API Operational Costs - Monthly - BALANCED NHSE Staff / Supplier Version, with Bottom-up hosting cost | S4: Key:
S5: Input
C6: Headline Item | D6: Monthly Cost (Low) | E6: Monthly Cost (High) | G6: Headline Item | H6: Monthly Cost (Low) | I6: Monthly Cost (High) | K6: Headline Item | L6: Monthly Cost (Low) | M6: Monthly Cost (High) | O6: Headline Item | P6: Monthly Cost (Low) | Q6: Monthly Cost (High) | S6: Calculated Output
C7: Cloud cost / hosting | D7: ='Hosting (Relative Sizing)'!$F$14 -> 25175.984 | G7: Cloud cost / hosting | H7: ='Hosting (Bottom-up)'!$E$8 -> 1788.4098 | K7: Cloud cost / hosting | L7: ='Hosting (Bottom-up)'!$E$8 -> 1788.4098 | O7: Cloud cost / hosting | P7: ='Hosting (Bottom-up)'!$E$8 -> 1788.4098
C8: Run / Maintain (incl OOH support) | D8: ='Run and Maintain'!$I$37 -> 88745.917 | E8: ='Run and Maintain'!$L$37 -> 185410.08 | G8: Run / Maintain (incl OOH support) | H8: ='Run and Maintain'!$I$37 -> 88745.917 | I8: ='Run and Maintain'!$L$37 -> 185410.08 | K8: Run / Maintain (incl OOH support) | L8: ='Run and Maintain'!$I$69 -> 42379.5 | M8: ='Run and Maintain'!$L$69 -> 77729 | O8: Run / Maintain (incl OOH support) | P8: ='Run and Maintain'!$I$100 -> 60895 | Q8: ='Run and Maintain'!$L$100 -> 108214.5
C9: ='Run and Maintain'!$D$24 -> Sub-Total Supplier In-hours | D9: ='Run and Maintain'!$I$24 -> 71668 | E9: ='Run and Maintain'!$L$24 -> 161253 | G9: ='Run and Maintain'!$D$24 -> Sub-Total Supplier In-hours | H9: ='Run and Maintain'!$I$24 -> 71668 | I9: ='Run and Maintain'!$L$24 -> 161253 | K9: ='Run and Maintain'!$D$56 -> Sub-Total Roles that would currently be supplier roles - In-hours | L9: ='Run and Maintain'!$I$56 -> 28025 | M9: ='Run and Maintain'!$L$56 -> 60942.5 | O9: ='Run and Maintain'!$D$56 -> Sub-Total Roles that would currently be supplier roles - In-hours | P9: ='Run and Maintain'!$I$87 -> 57076 | Q9: ='Run and Maintain'!$L$87 -> 100576.5
C10: ='Run and Maintain'!$D$27 -> Sub-Total Supplier Out-of-hours | D10: ='Run and Maintain'!$I$27 -> 5416.6667 | E10: ='Run and Maintain'!$L$27 -> 10833.333 | G10: ='Run and Maintain'!$D$27 -> Sub-Total Supplier Out-of-hours | H10: ='Run and Maintain'!$I$27 -> 5416.6667 | I10: ='Run and Maintain'!$L$27 -> 10833.333 | K10: ='Run and Maintain'!$D$59 -> Sub-Total Roles that would currently be supplier roles Out-of-hours | L10: ='Run and Maintain'!$I$59 -> 2693.25 | M10: ='Run and Maintain'!$L$59 -> 5386.5 | O10: ='Run and Maintain'!$D$59 -> Sub-Total Roles that would currently be supplier roles Out-of-hours | P10: ='Run and Maintain'!$I$90 -> 1895.25 | Q10: ='Run and Maintain'!$L$90 -> 3790.5
C11: ='Run and Maintain'!$D$34 -> Sub-Total NHSE Resource In-hours | D11: ='Run and Maintain'!$I$34 -> 11661.25 | E11: ='Run and Maintain'!$L$34 -> 13323.75 | G11: ='Run and Maintain'!$D$34 -> Sub-Total NHSE Resource In-hours | H11: ='Run and Maintain'!$I$34 -> 11661.25 | I11: ='Run and Maintain'!$L$34 -> 13323.75 | K11: ='Run and Maintain'!$D$66 -> Sub-Total Roles that are currently NHSE roles In-hours | L11: ='Run and Maintain'!$I$66 -> 11661.25 | M11: ='Run and Maintain'!$L$66 -> 11400 | O11: ='Run and Maintain'!$D$66 -> Sub-Total Roles that are currently NHSE roles In-hours | P11: ='Run and Maintain'!$I$97 -> 1923.75 | Q11: ='Run and Maintain'!$L$97 -> 3847.5
C12: =_xlfn.CONCAT('Run and Maintain'!$D$36," (Excluded)") -> Sub-Total NHSE Resource Out-of-hours (Excluded) | G12: =_xlfn.CONCAT('Run and Maintain'!$D$36," (Excluded)") -> Sub-Total NHSE Resource Out-of-hours (Excluded) | K12: =_xlfn.CONCAT('Run and Maintain'!$D$68," (Excluded)") -> Sub-Total NHSE Resource Out-of-hours (Excluded) | O12: =_xlfn.CONCAT('Run and Maintain'!$D$68," (Excluded)") -> Sub-Total NHSE Resource Out-of-hours (Excluded)
C13: Service Management | D13: ='Service Management'!$E$6 -> 10833.333 | E13: ='Service Management'!$F$6 -> 11666.667 | G13: Service Management | H13: ='Service Management'!$E$6 -> 10833.333 | I13: ='Service Management'!$F$6 -> 11666.667 | K13: Service Management | L13: ='Service Management'!$E$6 -> 10833.333 | M13: ='Service Management'!$F$6 -> 11666.667 | O13: Service Management | P13: ='Service Management'!$E$6 -> 10833.333 | Q13: ='Service Management'!$F$6 -> 11666.667
C14: Total | D14: =SUM(D7,D8,D13) -> 124755.23 | E14: =SUM(D7,E8,E13) -> 222252.73 | G14: Total | H14: =SUM(H7,H8,H13) -> 101367.66 | I14: =SUM(H7,I8,I13) -> 198865.16 | K14: Total | L14: =SUM(L7,L8,L13) -> 55001.243 | M14: =SUM(L7,M8,M13) -> 91184.076 | O14: Total | P14: =SUM(P7,P8,P13) -> 73516.743 | Q14: =SUM(P7,Q8,Q13) -> 121669.58
A16: API + UI -> | C16: API + UI Operational Costs - Monthly - Original Supplier Version, with Relative Hosting Cost
C18: Headline Item | D18: Monthly Cost (Low) | E18: Monthly Cost (High)
C19: Cloud cost / hosting | D19: ='Hosting (Relative Sizing)'!F25 -> 77759.6
C20: Run / Maintain (incl OOH support) | D20: ='Run and Maintain'!I138 -> 121038.08 | E20: ='Run and Maintain'!L138 -> 230202.58
C21: ='Run and Maintain'!$D$24 -> Sub-Total Supplier In-hours | D21: ='Run and Maintain'!$I$125 -> 98543.5 | E21: ='Run and Maintain'!$L$125 -> 206045.5
C22: ='Run and Maintain'!$D$27 -> Sub-Total Supplier Out-of-hours | D22: ='Run and Maintain'!$I$128 -> 10833.333 | E22: ='Run and Maintain'!$L$128 -> 10833.333
C23: ='Run and Maintain'!$D$34 -> Sub-Total NHSE Resource In-hours | D23: ='Run and Maintain'!$I$135 -> 11661.25 | E23: ='Run and Maintain'!$L$135 -> 13323.75
C24: =_xlfn.CONCAT('Run and Maintain'!$D$36," (Excluded)") -> Sub-Total NHSE Resource Out-of-hours (Excluded)
C25: Service Management | D25: ='Service Management'!$E$6 -> 10833.333 | E25: ='Service Management'!$F$6 -> 11666.667
C26: Total | D26: =SUM(D19,D20,D25) -> 209631.02 | E26: =SUM(D19,E20,E25) -> 319628.85
C30: Overarching Assumptions and Caveats
C31: Hosting figures should be considered very low confidence - further refinement of figures is required

Sheet Run and Maintain
B1: Improving how we connect: Run / Maintain Cost
B3: Assumptions
B4: Assume that there will be some transformation separately to pick up major feature rollouts, platform/architecture shifts, and reimagining user experiences.
B5: Assuming we'll cover off in Run & Maintain fixes, tech debt, patching, security fixes, etc. Excludes Run/Maintain of authoring tools
B6: For the "Low" option we have excluded Developer OOH, this is based on an assumption that we’ll have a rollback capability. Note that there is some residual risk could remain if a bug manifests out-of-hours that isn’t related to a specific release
B7: This profile should be reviewed with a team that operates a 24x7 API (e.g. NHS Login) to validate
B8: Rather than profiling specific performance testing resources, we are assuming that test engineering roles will be capable of carrying out performance testing
A10: API -> Supplier roles | E10: NHSE Staff Band | F10: # existing NHSE staff in Pathways | G10: Low - Run/Maintain - A lightweight team, focusing on fixes, debt, security but not new features or enhancements | J10: High - Run/Maintain plus CI - Full team, run/maintain plus minor feature delivery, to enhance based on user/operational priorities.
D11: API Run / Maintain Team | E11: Band | F11: FTE | G11: FTE | H11: Rate | I11: Monthly Cost | J11: FTE | K11: Rate | L11: Monthly Cost
B12: Supplier | C12: Core | D12: Lead Delivery Manager | E12: 8c | F12: 0 | G12: 0 | H12: ='Reference values'!$C$4 -> 943 | I12: =G12*H12*'Reference values'!$C$3 -> 0 | J12: 0.5 | K12: ='Reference values'!$C$4 -> 943 | L12: =J12*K12*'Reference values'!$C$3 -> 8958.5 | M12: CNI would definitely need 0.5 regardless
B13: Supplier | C13: Delivery | D13: Delivery Manager | E13: 8b | F13: 3 | G13: 0 | H13: ='Reference values'!$C$4 -> 943 | I13: =G13*H13*'Reference values'!$C$3 -> 0 | J13: 1 | K13: ='Reference values'!$C$4 -> 943 | L13: =J13*K13*'Reference values'!$C$3 -> 17917
B14: Supplier | C14: Delivery | D14: Service Delivery Manager *NEW* | E14: 8a | F14: 0 | G14: 0.5 | H14: ='Reference values'!$C$4 -> 943 | I14: =G14*H14*'Reference values'!$C$3 -> 8958.5 | J14: 0 | K14: ='Reference values'!$C$4 -> 943 | L14: =J14*K14*'Reference values'!$C$3 -> 0
B15: Supplier | C15: Product | D15: Product Manager | E15: 8a | F15: 3 | G15: 0 | H15: ='Reference values'!$C$4 -> 943 | I15: =G15*H15*'Reference values'!$C$3 -> 0 | J15: 1 | K15: ='Reference values'!$C$4 -> 943 | L15: =J15*K15*'Reference values'!$C$3 -> 17917
B16: Supplier | C16: Product | D16: Senior Business Analyst | E16: 8a | F16: 0 | G16: 0.5 | H16: ='Reference values'!$C$4 -> 943 | I16: =G16*H16*'Reference values'!$C$3 -> 8958.5 | J16: 1 | K16: ='Reference values'!$C$4 -> 943 | L16: =J16*K16*'Reference values'!$C$3 -> 17917
B17: Supplier | C17: Tech | D17: Lead Software Engineer | E17: 8c | F17: 0 | G17: 0.5 | H17: ='Reference values'!$C$4 -> 943 | I17: =G17*H17*'Reference values'!$C$3 -> 8958.5 | J17: 1 | K17: ='Reference values'!$C$4 -> 943 | L17: =J17*K17*'Reference values'!$C$3 -> 17917
B18: Supplier | C18: Tech | D18: Solution Architect | E18: 8b | F18: 0 | G18: 0 | H18: ='Reference values'!$C$4 -> 943 | I18: =G18*H18*'Reference values'!$C$3 -> 0 | J18: 0.5 | K18: ='Reference values'!$C$4 -> 943 | L18: =J18*K18*'Reference values'!$C$3 -> 8958.5
B19: Supplier | C19: Tech | D19: Senior Developer | E19: 8a | F19: 0 | G19: 0 | H19: ='Reference values'!$C$4 -> 943 | I19: =G19*H19*'Reference values'!$C$3 -> 0 | J19: 1 | K19: ='Reference values'!$C$4 -> 943 | L19: =J19*K19*'Reference values'!$C$3 -> 17917
B20: Supplier | C20: Tech | D20: Developer | E20: 7 | F20: 1 | G20: 1 | H20: ='Reference values'!$C$4 -> 943 | I20: =G20*H20*'Reference values'!$C$3 -> 17917 | J20: 1 | K20: ='Reference values'!$C$4 -> 943 | L20: =J20*K20*'Reference values'!$C$3 -> 17917
B21: Supplier | C21: Tech | D21: Platforms Engineer | E21: 8a | F21: 4 | G21: 1 | H21: ='Reference values'!$C$4 -> 943 | I21: =G21*H21*'Reference values'!$C$3 -> 17917 | J21: 1 | K21: ='Reference values'!$C$4 -> 943 | L21: =J21*K21*'Reference values'!$C$3 -> 17917
B22: Supplier | C22: Tech | D22: Test Engineer | E22: 7 | F22: 1 | G22: 0.5 | H22: ='Reference values'!$C$4 -> 943 | I22: =G22*H22*'Reference values'!$C$3 -> 8958.5 | J22: 0.5 | K22: ='Reference values'!$C$4 -> 943 | L22: =J22*K22*'Reference values'!$C$3 -> 8958.5
B23: Supplier | C23: UCD | D23: User Researcher | E23: 8a | F23: 2 | G23: 0 | H23: ='Reference values'!$C$4 -> 943 | I23: =G23*H23*'Reference values'!$C$3 -> 0 | J23: 0.5 | K23: ='Reference values'!$C$4 -> 943 | L23: =J23*K23*'Reference values'!$C$3 -> 8958.5
D24: Sub-Total Supplier In-hours | I24: =SUM(I12:I23) -> 71668 | L24: =SUM(L12:L23) -> 161253
B25: Supplier | C25: Tech OOH | D25: Platforms Engineer out of hours (OOH) | F25: 0 | G25: 1 | I25: =G25*'Reference values'!$C$10 -> 5416.6667 | J25: 1 | L25: =J25*'Reference values'!$C$10 -> 5416.6667 | M25: Need to check other platinum APIs and how they staff OOH. Requirement is root cause analysis and quick fixes, with a robust recovery plan
B26: Supplier | C26: Tech OOH | D26: Developer out of hours (OOH) | F26: 0 | G26: 0 | I26: =G26*'Reference values'!$C$10 -> 0 | J26: 1 | L26: =J26*'Reference values'!$C$10 -> 5416.6667 | M26: helpful to have a Developer on hand, essentially as a type of 3rd line consult support, but they thought that person's time would be seldom used. This should be 0.25 on the "High" profile, if we can share with other services, but for the purposes of ROM costing we'll assume that we need to pay for them to be available, so are plugging in 1.
D27: Sub-Total Supplier Out-of-hours | I27: =SUM(I25:I26) -> 5416.6667 | L27: =SUM(L25:L26) -> 10833.333
B28: NHSE | C28: Tech | D28: Technical Architect (8b) | E28: 8b | F28: 0 | G28: 0.25 | H28: ='Reference values'!$C$7 -> 405 | I28: =G28*H28*'Reference values'!$C$3 -> 1923.75 | J28: 0.25 | K28: ='Reference values'!$C$7 -> 405 | L28: =J28*K28*'Reference values'!$C$3 -> 1923.75
B29: NHSE | C29: Delivery | D29: Programme Manager (8c) | E29: 8c | F29: 2 | G29: 0.25 | H29: ='Reference values'!$C$6 -> 500 | I29: =G29*H29*'Reference values'!$C$3 -> 2375 | J29: 0.25 | K29: ='Reference values'!$C$6 -> 500 | L29: =J29*K29*'Reference values'!$C$3 -> 2375
B30: NHSE | C30: Tech | D30: Principal Systems Engineer *NEW* | E30: 8c | F30: 0 | G30: 0.25 | H30: ='Reference values'!$C$6 -> 500 | I30: =G30*H30*'Reference values'!$C$3 -> 2375 | J30: 0.25 | K30: ='Reference values'!$C$6 -> 500 | L30: =J30*K30*'Reference values'!$C$3 -> 2375
B31: NHSE | C31: Delivery | D31: Implementation Manager (8a) | E31: 8a | F31: 6 | G31: 0.5 | H31: ='Reference values'!$C$8 -> 350 | I31: =G31*H31*'Reference values'!$C$3 -> 3325 | J31: 0.5 | K31: ='Reference values'!$C$8 -> 350 | L31: =J31*K31*'Reference values'!$C$3 -> 3325
B32: NHSE | C32: Clinical | D32: Clinical Author (8a) | E32: 8a | F32: 13 | G32: 0.25 | H32: ='Reference values'!$C$8 -> 350 | I32: =G32*H32*'Reference values'!$C$3 -> 1662.5 | J32: 0.5 | K32: ='Reference values'!$C$8 -> 350 | L32: =J32*K32*'Reference values'!$C$3 -> 3325
B33: NHSE | C33: Clinical | D33: Clinical Author (8a medic) | E33: 8a medic | F33: - | G33: 0 | H33: ='Reference values'!$C$9 -> 700 | I33: =G33*H33*'Reference values'!$C$3 -> 0 | J33: 0 | K33: ='Reference values'!$C$9 -> 700 | L33: =J33*K33*'Reference values'!$C$3 -> 0
D34: Sub-Total NHSE Resource In-hours | I34: =SUM(I28:I33) -> 11661.25 | L34: =SUM(L28:L33) -> 13323.75
B35: NHSE OOO | C35: Clinical | D35: Clinical Author (8a) | E35: 8a | F35: - | G35: 0.405 | H35: ='Reference values'!$C$8 -> 350 | I35: =G35*H35*'Reference values'!$C$3 -> 2693.25 | J35: 0.405 | K35: ='Reference values'!$C$8 -> 350 | L35: =J35*K35*'Reference values'!$C$3 -> 2693.25 | M35: 9 clinical authors in the pool, 4.5% of their cost is for OOH. So OOH is equivalent of 0.405 FTE | N35: Q: what type of OOH issue does this cover?
D36: Sub-Total NHSE Resource Out-of-hours | I36: =SUM(I35) -> 2693.25 | L36: =SUM(L35) -> 2693.25
D37: Total excluding NHSE Resource OOH | I37: =SUM(I24,I27,I34) -> 88745.917 | L37: =SUM(L24,L27,L34) -> 185410.08
E42: NHSE Staff Band | F42: # existing NHSE staff in Pathways | G42: Low - Run/Maintain - A lightweight team, focusing on fixes, debt, security but not new features or enhancements | J42: High - Run/Maintain plus CI - Full team, run/maintain plus minor feature delivery, to enhance based on user/operational priorities.
A43: API -> All NHSE | D43: API Run / Maintain Team | E43: Band | F43: FTE | G43: FTE | H43: Rate | I43: Monthly Cost | J43: FTE | K43: Rate | L43: Monthly Cost
B44: NHSE | C44: Core | D44: Lead Delivery Manager | E44: 8c | F44: 0 | G44: 0 | H44: ='Reference values'!$C$6 -> 500 | I44: =G44*H44*'Reference values'!$C$3 -> 0 | J44: 0 | K44: ='Reference values'!$C$6 -> 500 | L44: =J44*K44*'Reference values'!$C$3 -> 0 | M44: COVERED BY PROG MGR
B45: NHSE | C45: Delivery | D45: Delivery Manager | E45: 8b | F45: 3 | G45: 0 | H45: ='Reference values'!$C$7 -> 405 | I45: =G45*H45*'Reference values'!$C$3 -> 0 | J45: 1 | K45: ='Reference values'!$C$7 -> 405 | L45: =J45*K45*'Reference values'!$C$3 -> 7695
B46: NHSE | C46: Delivery | D46: Service Delivery Manager *NEW* | E46: 8a | F46: 0 | G46: 0.5 | H46: ='Reference values'!$C$8 -> 350 | I46: =G46*H46*'Reference values'!$C$3 -> 3325 | J46: 0 | K46: ='Reference values'!$C$8 -> 350 | L46: =J46*K46*'Reference values'!$C$3 -> 0
...

Sheet Service Management
B1: Improving how we connect: Service Management
B5: Please find below a summary of the key details, which we’ll discuss and finalise once we receive the NWR. | E5: Low (Monthly) | F5: High (Monthly)
B6: The estimated cost outlined applies to both options we discussed and reflects a Platinum service level. Based on our current understanding, we anticipate an additional annual cost of £130,000–£140,000 on top of your existing recharge. | E6: =130000/12 -> 10833.333 | F6: =140000/12 -> 11666.667
B7: This estimate includes: - Service Management - ITOC - NSD - Service Bridge
B8: It does not include: - Onboarding resource - Solutions assurance resource - Clinical assurance resource - Clinical resource for live incidents
B9: Additionally, the interface option presented on slide 14 of your slide pack would need to be considered if a separate service desk is required for end users.

Sheet Hosting (Relative Sizing)
B1: Improving how we connect: Hosting cost
A3: API -> | F3: We assume that transition is complete and we will have 100% uptake through the API, for the purposes of these costings
F4: We are assuming that because in 2021-22, NHS login handled 1.1 billion logins, they could be doing 1.5 billion/year now
F5: We assume - based on the reference figures at the bottom of this sheet - that we might do 600m per year API calls
F6: Caveats: we believe that we will end up simpler architecturally than NHS Login, but offsetting this, they are likely to be more optimised at this stage.
F7: Caveats: we believe that NHS login are likely to be quite optimised in their cloud usage at this stage, given how long they have been live for.
F8: Caveats: Based on these assumptions and the caveats above, this figure should be treated as low confidence - and we will refine this as our architecture design is refined
F10: 85054 | G10: Monthly hosting cost for all NHS Login
F11: 1500000000 | G11: Assumed number of transactions per year for NHS login
F12: =600000000 -> 600000000 | G12: Assumed number of transactions per year for API
F13: =F12/F11*F10 -> 34021.6 | G13: Projected monthly hosting cost for our API, assuming a similar cost per transaction as NHS Login
F14: =F13*'Reference values'!$C$11 -> 25175.984 | G14: Projected monthly hosting cost for our API, assuming a similar cost per transaction as NHS Login
A17: API + UI -> | F17: We assume that transition is complete and we will have 100% uptake through the API, for the purposes of these costings
F18: We assume - based on the reference figures at the bottom of this sheet - that 2/3rd of all triages will go through our UI, and the other 1/3rd goes via 111 Online (so we need to handle double the volume)
F19: Caveat: 111 Online are likely to reduce hosting cost in the future through cloud cost optimisation
F20: Caveat: We do expect our architecture to be simpler than 111 Online, so the calculated figure should be treated as an upper limit
F21: Caveats: Based on these assumptions and the caveats above, this figure should be treated as low confidence - and would be refined in a UI alpha
F23: 52540.27 | G23: per month for all 111 Online hosting
F24: =F23*2 -> 105080.54 | G24: per month for a Pathways UI (for telephony)
F25: =F24*'Reference values'!$C$11 -> 77759.6 | G25: per month for a Pathways UI (for telephony) - in £
A32: Other reference information
A47: Volumes
B48: Service | C48: Triages | D48: Average no of questions per triage | E48: Questions per year
B49: 111 Online | C49: 7794040 | D49: 11 | E49: =C49*D49 -> 85734440
B50: 111 Telephony | C50: 19514394 | D50: 20 | E50: =C50*D50 -> 390287880
B51: Ambulance 999 | C51: 5099768 | D51: 19 | E51: =C51*D51 -> 96895592
B52: Emergency Department Streaming & Redirection | C52: 358579 | D52: 17 | E52: =C52*D52 -> 6095843
B53: Total | C53: 32766781 | E53: =SUM(E49:E52) -> 579013755

Sheet Hosting (Bottom-up)
B1: Improving how we connect: Hosting - Bottom up
B4: Source material:
B5: See Confluence for cost calculation - https://nhsd-confluence.digital.nhs.uk/spaces/NPR/pages/1180211738/Triage+API+Run+cost+estimate+-+pre-Alpha | E5: 805.59 | F5: Monthly cost from the cost calculator
E6: 3 | F6: Contingency multiplier
E7: =E5*E6 -> 2416.77 | F7: Monthly cost including contingency
B8: Key assumptions / caveats | E8: =E7*'Reference values'!$C$11 -> 1788.4098 | F8: Monthly cost
B9: Costs are based on the current architecture design. Some elements may need to be extended in future (e.g. for TOM)
B10: Costs will be reviewed and refreshed in Beta

Sheet Reference values
B2: Description | C2: Value
B3: Assumed Days per Month | C3: 19
B4: Day Rate for Supplier Roles | C4: 943 | E4: 943
B5: Day Rate for NHSE Roles - 7 | C5: 350 | D5: (just using the 8a one for now) | E5: 500
B6: Day Rate for NHSE Roles - 8c | C6: 500 | E6: 405
B7: Day Rate for NHSE Roles - 8b | C7: 405 | E7: 350
B8: Day Rate for NHSE Roles - 8a (incl nurse) | C8: 350 | E8: 700
B9: Day Rate for NHSE Roles - 8a medic | C9: 700 | D9: Note: This is based on a rough cost of 130k/annum for two OOH staff that was provided to FtRS. This assumed transformed services and use of serverless, its based on level of support we see in FtRS. The figures will need to be revised once we have a better handle on the expected number of issues that might be experienced with a Pathways API | E9: =130000/2/12 -> 5416.6667
B10: Monthly OOH cost for a Supplier Role | C10: =130000/2/12 -> 5416.6667
B11: Exchange rate. USD to GBP, $1 = | C11: 0.74

Sheet Sep 2026 Refresh
C2: rough current monthly cost | D2: 400
C3: rough current requests per month | D3: 50000
C4: rough current cost per request | D4: =D2/D3 -> 0.008
C6: total end state requests per year | D6: ='Hosting (Relative Sizing)'!E53 -> 579013755
C7: total end stat cost per year | D7: =D4*D6 -> 4632110
